<?xml version="1.0" ?>
<robot name="Robot" xmlns:xacro="http://wiki.ros.org/xacro">
<gazebo>
    <plugin filename="libgazebo_ros_control.so" name="ros_control">
      <!--robotNamespace>/</robotNamespace-->
      <!--robotSimType>gazebo_ros_control/DefaultRobotHWSim</robotSimType-->
    </plugin>
    <!--
    <plugin name="gazebo_ros_power_monitor_controller" filename="libgazebo_ros_power_monitor.so">
      <alwaysOn>true</alwaysOn>
      <updateRate>1.0</updateRate>
      <timeout>5</timeout>
      <powerStateTopic>power_state</powerStateTopic>
      <powerStateRate>10.0</powerStateRate>
      <fullChargeCapacity>87.78</fullChargeCapacity>     
      <dischargeRate>-474</dischargeRate>
      <chargeRate>525</chargeRate>
      <dischargeVoltage>15.52</dischargeVoltage>
      <chargeVoltage>16.41</chargeVoltage>
    </plugin>
-->
  </gazebo>
<material name="silver">
  <color rgba="0.700 0.700 0.700 1.000"/>
</material>

<link name="base_link">
  <inertial>
    <origin xyz="0.0 0.0 0.0" rpy="0 0 0"/>
    <mass value="0.0"/>
    <inertia ixx="0.0" iyy="0.0" izz="0.0" ixy="0.0" iyz="0.0" ixz="0.0"/>
  </inertial>
  <visual>
    <origin xyz="0 0 0" rpy="0 0 0"/>
    <geometry>
      <mesh filename="meshes/base_link.stl" scale="0.001 0.001 0.001"/>
    </geometry>
    <material name="silver"/>
    <material/>
  </visual>
  <collision>
    <origin xyz="0 0 0" rpy="0 0 0"/>
    <geometry>
      <mesh filename="meshes/base_link.stl" scale="0.001 0.001 0.001"/>
    </geometry>
  </collision>
</link>

<link name="placa_base1">
  <inertial>
    <origin xyz="0.40877638686219 -1.4600099364657049 -0.6525991128809477" rpy="0 0 0"/>
    <mass value="375.4086793589621"/>
    <inertia ixx="38.02067284848687" iyy="20.791186447290116" izz="56.84458630240343" ixy="-7.702526247044261e-06" iyz="-0.11817074023767304" ixz="-4.431769440316202e-08"/>
  </inertial>
  <visual>
    <origin xyz="0.011211 -2.022818 -0.91961" rpy="0 0 0"/>
    <geometry>
      <mesh filename="meshes/placa_base1.stl" scale="0.001 0.001 0.001"/>
    </geometry>
    <material name="silver"/>
    <material/>
  </visual>
  <collision>
    <origin xyz="0.011211 -2.022818 -0.91961" rpy="0 0 0"/>
    <geometry>
      <mesh filename="meshes/placa_base1.stl" scale="0.001 0.001 0.001"/>
    </geometry>
  </collision>
</link>

<link name="base_r1">
  <inertial>
    <origin xyz="-0.07435754686676044 -0.0004390727397289851 0.1163853188916053" rpy="0 0 0"/>
    <mass value="570.670009527453"/>
    <inertia ixx="15.007731795878271" iyy="29.8002880804859" izz="35.94575537583742" ixy="-0.008385642875907706" iyz="-0.049964601328127856" ixz="0.9746269253855928"/>
  </inertial>
  <visual>
    <origin xyz="-0.397565 -0.568456 -0.317359" rpy="0 0 0"/>
    <geometry>
      <mesh filename="meshes/base_r1.stl" scale="0.001 0.001 0.001"/>
    </geometry>
    <material name="silver"/>
    <material/>
  </visual>
  <collision>
    <origin xyz="-0.397565 -0.568456 -0.317359" rpy="0 0 0"/>
    <geometry>
      <mesh filename="meshes/base_r1.stl" scale="0.001 0.001 0.001"/>
    </geometry>
  </collision>
</link>

<link name="s_axis1">
  <inertial>
    <origin xyz="0.24654028338249517 -0.04135438603178743 0.201938348833121" rpy="0 0 0"/>
    <mass value="704.6084530701154"/>
    <inertia ixx="48.865557050075154" iyy="116.94190982276893" izz="129.87540407311695" ixy="-10.669964153775169" iyz="3.7822918762317954" ixz="12.845024374148181"/>
  </inertial>
  <visual>
    <origin xyz="-0.397565 -0.568456 -0.609359" rpy="0 0 0"/>
    <geometry>
      <mesh filename="meshes/s_axis1.stl" scale="0.001 0.001 0.001"/>
    </geometry>
    <material name="silver"/>
    <material/>
  </visual>
  <collision>
    <origin xyz="-0.397565 -0.568456 -0.609359" rpy="0 0 0"/>
    <geometry>
      <mesh filename="meshes/s_axis1.stl" scale="0.001 0.001 0.001"/>
    </geometry>
  </collision>
</link>

<link name="l_axis1">
  <inertial>
    <origin xyz="0.027205812442917532 -0.16142313250842483 0.46588585894516765" rpy="0 0 0"/>
    <mass value="552.7971519942739"/>
    <inertia ixx="81.3413160735854" iyy="82.03600982568787" izz="9.751944802216144" ixy="-0.6479570420340508" iyz="8.230717944273692" ixz="1.7973074241333507"/>
  </inertial>
  <visual>
    <origin xyz="-1.137571 -0.490512 -0.757359" rpy="0 0 0"/>
    <geometry>
      <mesh filename="meshes/l_axis1.stl" scale="0.001 0.001 0.001"/>
    </geometry>
    <material name="silver"/>
    <material/>
  </visual>
  <collision>
    <origin xyz="-1.137571 -0.490512 -0.757359" rpy="0 0 0"/>
    <geometry>
      <mesh filename="meshes/l_axis1.stl" scale="0.001 0.001 0.001"/>
    </geometry>
  </collision>
</link>

<link name="u_axis1">
  <inertial>
    <origin xyz="0.2916606047917749 0.2143462434100445 0.14928647205424506" rpy="0 0 0"/>
    <mass value="483.4234110989252"/>
    <inertia ixx="14.609702279059547" iyy="57.21389978569323" izz="54.57939855035738" ixy="-6.234944861433519" iyz="-3.416392719524424" ixz="-11.507639554971547"/>
  </inertial>
  <visual>
    <origin xyz="-1.137534 -0.301512 -1.907359" rpy="0 0 0"/>
    <geometry>
      <mesh filename="meshes/u_axis1.stl" scale="0.001 0.001 0.001"/>
    </geometry>
    <material name="silver"/>
    <material/>
  </visual>
  <collision>
    <origin xyz="-1.137534 -0.301512 -1.907359" rpy="0 0 0"/>
    <geometry>
      <mesh filename="meshes/u_axis1.stl" scale="0.001 0.001 0.001"/>
    </geometry>
  </collision>
</link>

<link name="r_axis1">
  <inertial>
    <origin xyz="0.1685563993211039 -0.07412707539147773 -0.0004901924830997828" rpy="0 0 0"/>
    <mass value="8.899946281447061"/>
    <inertia ixx="0.06127843254422061" iyy="0.08034237671594724" izz="0.08937108282597706" ixy="0.018596107290122177" iyz="0.00024897477269725243" ixz="8.428900012091844e-05"/>
  </inertial>
  <visual>
    <origin xyz="-2.166033 -0.568589 -2.157277" rpy="0 0 0"/>
    <geometry>
      <mesh filename="meshes/r_axis1.stl" scale="0.001 0.001 0.001"/>
    </geometry>
    <material name="silver"/>
    <material/>
  </visual>
  <collision>
    <origin xyz="-2.166033 -0.568589 -2.157277" rpy="0 0 0"/>
    <geometry>
      <mesh filename="meshes/r_axis1.stl" scale="0.001 0.001 0.001"/>
    </geometry>
  </collision>
</link>

<link name="b_axis1">
  <inertial>
    <origin xyz="0.10691585220915778 0.13249813747746225 1.7028415353781412e-05" rpy="0 0 0"/>
    <mass value="45.978906535968754"/>
    <inertia ixx="0.38205481909454875" iyy="0.49014927642423345" izz="0.5800243135331584" ixy="0.018167428092283444" iyz="0.00018797387867408588" ixz="-1.824754548351848e-05"/>
  </inertial>
  <visual>
    <origin xyz="-2.362546 -0.399739 -2.157247" rpy="0 0 0"/>
    <geometry>
      <mesh filename="meshes/b_axis1.stl" scale="0.001 0.001 0.001"/>
    </geometry>
    <material name="silver"/>
    <material/>
  </visual>
  <collision>
    <origin xyz="-2.362546 -0.399739 -2.157247" rpy="0 0 0"/>
    <geometry>
      <mesh filename="meshes/b_axis1.stl" scale="0.001 0.001 0.001"/>
    </geometry>
  </collision>
</link>

<link name="t_axis1">
  <inertial>
    <origin xyz="0.014205681418202776 1.4136109089957216e-06 -3.8225856600071495e-06" rpy="0 0 0"/>
    <mass value="5.836276011069466"/>
    <inertia ixx="0.025268192829255298" iyy="0.013037480764481302" izz="0.013092889235352345" ixy="9.167754582151133e-07" iyz="-9.661189421805716e-07" ixz="-3.617309602077512e-06"/>
  </inertial>
  <visual>
    <origin xyz="-2.582537 -0.527255 -2.157192" rpy="0 0 0"/>
    <geometry>
      <mesh filename="meshes/t_axis1.stl" scale="0.001 0.001 0.001"/>
    </geometry>
    <material name="silver"/>
    <material/>
  </visual>
  <collision>
    <origin xyz="-2.582537 -0.527255 -2.157192" rpy="0 0 0"/>
    <geometry>
      <mesh filename="meshes/t_axis1.stl" scale="0.001 0.001 0.001"/>
    </geometry>
  </collision>
</link>

<link name="balancer_21">
  <inertial>
    <origin xyz="-1.0071355171291383 -1.141364295073391 -0.48045645693854944" rpy="0 0 0"/>
    <mass value="34.720628844492076"/>
    <inertia ixx="0.3660507282264831" iyy="6.432975989754773" izz="6.085231601474279" ixy="0.006621337131715421" iyz="-0.0015655726474221865" ixz="1.4321732317723797"/>
  </inertial>
  <visual>
    <origin xyz="-1.412434 -1.519454 -1.498385" rpy="0 0 0"/>
    <geometry>
      <mesh filename="meshes/balancer_21.stl" scale="0.001 0.001 0.001"/>
    </geometry>
    <material name="silver"/>
    <material/>
  </visual>
  <collision>
    <origin xyz="-1.412434 -1.519454 -1.498385" rpy="0 0 0"/>
    <geometry>
      <mesh filename="meshes/balancer_21.stl" scale="0.001 0.001 0.001"/>
    </geometry>
  </collision>
</link>

<link name="balancer_11">
  <inertial>
    <origin xyz="0.27454396791234575 -1.5743809510766291 -0.7961805409798757" rpy="0 0 0"/>
    <mass value="1052.0941459866974"/>
    <inertia ixx="24.42331144454556" iyy="134.39070049428642" izz="128.35779332816" ixy="-0.008243507566618291" iyz="0.001952817510357363" ixz="26.04558294972415"/>
  </inertial>
  <visual>
    <origin xyz="0.078722 -1.952822 -1.863697" rpy="0 0 0"/>
    <geometry>
      <mesh filename="meshes/balancer_11.stl" scale="0.001 0.001 0.001"/>
    </geometry>
    <material name="silver"/>
    <material/>
  </visual>
  <collision>
    <origin xyz="0.078722 -1.952822 -1.863697" rpy="0 0 0"/>
    <geometry>
      <mesh filename="meshes/balancer_11.stl" scale="0.001 0.001 0.001"/>
    </geometry>
  </collision>
</link>

<joint name="base_link1" type="prismatic">
  <origin xyz="-0.011211 2.022818 0.91961" rpy="0 0 0"/>
  <parent link="base_link"/>
  <child link="placa_base1"/>
  <axis xyz="0.0 -1.0 0.0"/>
  <limit upper="-0.01" lower="-1.9" effort="100" velocity="100"/>
</joint>
<transmission name="base_link1_tran">
  <type>transmission_interface/SimpleTransmission</type>
  <joint name="base_link1">
    <hardwareInterface>PositionJointInterface</hardwareInterface>
  </joint>
  <actuator name="base_link1_actr">
    <hardwareInterface>PositionJointInterface</hardwareInterface>
    <mechanicalReduction>1</mechanicalReduction>
  </actuator>
</transmission>

<joint name="rig1" type="fixed">
  <origin xyz="0.408776 -1.454362 -0.602251" rpy="0 0 0"/>
  <parent link="placa_base1"/>
  <child link="base_r1"/>
</joint>

<joint name="link1_link2" type="continuous">
  <origin xyz="0.0 0.0 0.292" rpy="0 0 0"/>
  <parent link="base_r1"/>
  <child link="s_axis1"/>
  <axis xyz="0.0 0.0 1.0"/>
</joint>
<transmission name="link1_link2_tran">
  <type>transmission_interface/SimpleTransmission</type>
  <joint name="link1_link2">
    <hardwareInterface>PositionJointInterface</hardwareInterface>
  </joint>
  <actuator name="link1_link2_actr">
    <hardwareInterface>PositionJointInterface</hardwareInterface>
    <mechanicalReduction>1</mechanicalReduction>
  </actuator>
</transmission>

<joint name="link2_link3" type="revolute">
  <origin xyz="0.740006 -0.077944 0.148" rpy="0 0 0"/>
  <parent link="s_axis1"/>
  <child link="l_axis1"/>
  <axis xyz="7.5e-05 -1.0 0.0"/>
  <limit upper="0.610865" lower="-1.22173" effort="100" velocity="100"/>
</joint>
<transmission name="link2_link3_tran">
  <type>transmission_interface/SimpleTransmission</type>
  <joint name="link2_link3">
    <hardwareInterface>PositionJointInterface</hardwareInterface>
  </joint>
  <actuator name="link2_link3_actr">
    <hardwareInterface>PositionJointInterface</hardwareInterface>
    <mechanicalReduction>1</mechanicalReduction>
  </actuator>
</transmission>

<joint name="link3_link4" type="continuous">
  <origin xyz="-3.7e-05 -0.189 1.15" rpy="0 0 0"/>
  <parent link="l_axis1"/>
  <child link="u_axis1"/>
  <axis xyz="-7.5e-05 1.0 -0.0"/>
</joint>
<transmission name="link3_link4_tran">
  <type>transmission_interface/SimpleTransmission</type>
  <joint name="link3_link4">
    <hardwareInterface>PositionJointInterface</hardwareInterface>
  </joint>
  <actuator name="link3_link4_actr">
    <hardwareInterface>PositionJointInterface</hardwareInterface>
    <mechanicalReduction>1</mechanicalReduction>
  </actuator>
</transmission>

<joint name="link4_link5" type="continuous">
  <origin xyz="1.028499 0.267077 0.249918" rpy="0 0 0"/>
  <parent link="u_axis1"/>
  <child link="r_axis1"/>
  <axis xyz="1.0 7.5e-05 -8e-05"/>
</joint>
<transmission name="link4_link5_tran">
  <type>transmission_interface/SimpleTransmission</type>
  <joint name="link4_link5">
    <hardwareInterface>PositionJointInterface</hardwareInterface>
  </joint>
  <actuator name="link4_link5_actr">
    <hardwareInterface>PositionJointInterface</hardwareInterface>
    <mechanicalReduction>1</mechanicalReduction>
  </actuator>
</transmission>

<joint name="link5_link6" type="revolute">
  <origin xyz="0.196513 -0.16885 -3e-05" rpy="0 0 0"/>
  <parent link="r_axis1"/>
  <child link="b_axis1"/>
  <axis xyz="7.5e-05 -1.0 -8.2e-05"/>
  <limit upper="2.094395" lower="-2.094395" effort="100" velocity="100"/>
</joint>
<transmission name="link5_link6_tran">
  <type>transmission_interface/SimpleTransmission</type>
  <joint name="link5_link6">
    <hardwareInterface>PositionJointInterface</hardwareInterface>
  </joint>
  <actuator name="link5_link6_actr">
    <hardwareInterface>PositionJointInterface</hardwareInterface>
    <mechanicalReduction>1</mechanicalReduction>
  </actuator>
</transmission>

<joint name="link6_link7" type="continuous">
  <origin xyz="0.219991 0.127516 -5.5e-05" rpy="0 0 0"/>
  <parent link="b_axis1"/>
  <child link="t_axis1"/>
  <axis xyz="1.0 7.5e-05 -0.000297"/>
</joint>
<transmission name="link6_link7_tran">
  <type>transmission_interface/SimpleTransmission</type>
  <joint name="link6_link7">
    <hardwareInterface>PositionJointInterface</hardwareInterface>
  </joint>
  <actuator name="link6_link7_actr">
    <hardwareInterface>PositionJointInterface</hardwareInterface>
    <mechanicalReduction>1</mechanicalReduction>
  </actuator>
</transmission>

<gazebo reference="base_link">
    <selfCollide>true</selfCollide>
  </gazebo>
  <gazebo reference="placa_base1">
    <selfCollide>true</selfCollide>
  </gazebo>
  <gazebo reference="base_r1">
    <selfCollide>true</selfCollide>
  </gazebo>
  <gazebo reference="s_axis1">
    <selfCollide>true</selfCollide>
  </gazebo>
  <gazebo reference="l_axis1">
    <selfCollide>true</selfCollide>
  </gazebo>
  <gazebo reference="u_axis1">
    <selfCollide>true</selfCollide>
  </gazebo>
  <gazebo reference="r_axis1">
    <selfCollide>true</selfCollide>
  </gazebo>
  <gazebo reference="b_axis1">
    <selfCollide>true</selfCollide>
  </gazebo>
  <gazebo reference="t_axis1">
    <selfCollide>true</selfCollide>
  </gazebo>
  <gazebo reference="balancer_21">
    <selfCollide>true</selfCollide>
  </gazebo>
  <gazebo reference="balancer_11">
    <selfCollide>true</selfCollide>
  </gazebo>

<joint name="rig2" type="fixed">
  <origin xyz="1.014869 0.950998 0.889026" rpy="0 0 0"/>
  <parent link="s_axis1"/>
  <child link="balancer_21"/>
</joint>

<joint name="rig3" type="fixed">
  <origin xyz="-1.491156 0.433368 0.365312" rpy="0 0 0"/>
  <parent link="balancer_21"/>
  <child link="balancer_11"/>
</joint>

</robot>
